{"metadata": {"dbt_schema_version": "https://schemas.getdbt.com/dbt/run-results/v4.json", "dbt_version": "1.3.1", "generated_at": "2022-12-21T09:34:39.843116Z", "invocation_id": "518058dd-6edb-4800-98c1-e714274f9c8e", "env": {}}, "results": [{"status": "error", "timing": [], "thread_id": "Thread-1", "execution_time": 7.440799951553345, "adapter_response": {}, "message": "Database Error in model QA_Stored_Proc (models/Store_Procedure/QA_Stored_Proc.py)\n  100357 (P0000): Python Interpreter Error:\n  Traceback (most recent call last):\n    File \"_udf_code.py\", line 84, in main\n    File \"_udf_code.py\", line 79, in materialize\n    File \"/usr/lib/python_udf/47ac6f7810336782a8a84642d0585140cbda21497ce211fa2f77fd748a736942/lib/python3.8/site-packages/snowflake/snowpark/_internal/telemetry.py\", line 161, in wrap\n      result = func(*args, **kwargs)\n    File \"/usr/lib/python_udf/47ac6f7810336782a8a84642d0585140cbda21497ce211fa2f77fd748a736942/lib/python3.8/site-packages/snowflake/snowpark/dataframe_writer.py\", line 193, in save_as_table\n      result = session._conn.execute(\n    File \"/usr/lib/python_udf/47ac6f7810336782a8a84642d0585140cbda21497ce211fa2f77fd748a736942/lib/python3.8/site-packages/snowflake/snowpark/_internal/server_connection.py\", line 406, in execute\n      result_set, result_meta = self.get_result_set(\n    File \"/usr/lib/python_udf/47ac6f7810336782a8a84642d0585140cbda21497ce211fa2f77fd748a736942/lib/python3.8/site-packages/snowflake/snowpark/_internal/analyzer/snowflake_plan.py\", line 154, in wrap\n      raise ne.with_traceback(tb) from None\n    File \"/usr/lib/python_udf/47ac6f7810336782a8a84642d0585140cbda21497ce211fa2f77fd748a736942/lib/python3.8/site-packages/snowflake/snowpark/_internal/analyzer/snowflake_plan.py\", line 87, in wrap\n      return func(*args, **kwargs)\n    File \"/usr/lib/python_udf/47ac6f7810336782a8a84642d0585140cbda21497ce211fa2f77fd748a736942/lib/python3.8/site-packages/snowflake/snowpark/_internal/server_connection.py\", line 494, in get_result_set\n      result = self.run_query(\n    File \"/usr/lib/python_udf/47ac6f7810336782a8a84642d0585140cbda21497ce211fa2f77fd748a736942/lib/python3.8/site-packages/snowflake/snowpark/_internal/server_connection.py\", line 104, in wrap\n      raise ex\n    File \"/usr/lib/python_udf/47ac6f7810336782a8a84642d0585140cbda21497ce211fa2f77fd748a736942/lib/python3.8/site-packages/snowflake/snowpark/_internal/server_connection.py\", line 98, in wrap\n      return func(*args, **kwargs)\n    File \"/usr/lib/python_udf/47ac6f7810336782a8a84642d0585140cbda21497ce211fa2f77fd748a736942/lib/python3.8/site-packages/snowflake/snowpark/_internal/server_connection.py\", line 333, in run_query\n      raise ex\n    File \"/usr/lib/python_udf/47ac6f7810336782a8a84642d0585140cbda21497ce211fa2f77fd748a736942/lib/python3.8/site-packages/snowflake/snowpark/_internal/server_connection.py\", line 317, in run_query\n      results_cursor = self._cursor.execute(query, **kwargs)\n    File \"/usr/lib/python_udf/47ac6f7810336782a8a84642d0585140cbda21497ce211fa2f77fd748a736942/lib/python3.8/site-packages/snowflake/connector/cursor.py\", line 822, in execute\n      Error.errorhandler_wrapper(\n    File \"/usr/lib/python_udf/47ac6f7810336782a8a84642d0585140cbda21497ce211fa2f77fd748a736942/lib/python3.8/site-packages/snowflake/connector/errors.py\", line 229, in errorhandler_wrapper\n      handed_over = Error.hand_to_other_handler(\n    File \"/usr/lib/python_udf/47ac6f7810336782a8a84642d0585140cbda21497ce211fa2f77fd748a736942/lib/python3.8/site-packages/snowflake/connector/errors.py\", line 284, in hand_to_other_handler\n      cursor.errorhandler(connection, cursor, error_class, error_value)\n    File \"/usr/lib/python_udf/47ac6f7810336782a8a84642d0585140cbda21497ce211fa2f77fd748a736942/lib/python3.8/site-packages/snowflake/connector/errors.py\", line 163, in default_errorhandler\n      raise error_class(\n  snowflake.snowpark.exceptions.SnowparkSQLException: (1304): 01a91d1e-0000-e173-0002-fb82002821c6: 100131 (P0000): Execution error in store procedure QA_FRAMEWORK:\n  JavaScript compilation error: Uncaught SyntaxError: Unexpected identifier in MAIL at '  email=  call system$send_email('my_email_int','sunilm@booleandata.com,anilk@booleandata.com','Email Alert: Alert Mail For Customer Data .','No. of TABLE_NAME Are Not Exceeded More Than 5, Please Take Appropiate Action..!');' position 15\n  At Snowflake.execute, line 43 position 16\n   in function QA_STORED_PROC__DBT_SP with handler main\n  compiled Code at target/run/my_new_project/models/Store_Procedure/QA_Stored_Proc.py", "failures": null, "unique_id": "model.my_new_project.QA_Stored_Proc"}], "elapsed_time": 8.910097122192383, "args": {"write_json": true, "use_colors": true, "printer_width": 80, "version_check": true, "partial_parse": true, "static_parser": true, "profiles_dir": "/usr/src/develop/.dbt", "send_anonymous_usage_stats": true, "event_buffer_size": 100000, "quiet": false, "no_print": false, "vars": "{}\n", "select": ["QA_Stored_Proc"], "which": "run", "rpc_method": "run", "indirect_selection": "eager"}}